Workbook

Sheet Precon Decks
A1: Include | B1: Release Date | C1: Code | D1: Set Name | E1: Deck Name | F1: Commander Mana | G1: Power | H1: Bracket | I1: Game Speed | J1: Threat Perception | K1: Archetype | L1: Tags | M1: Pod Rand | N1: Duel Rand | O1: Commander | P1: Deck Type
A2: 1 | B2: 2021-09-24 | C2: MIC | D2: Midnight Hunt Commander | E2: Coven Counters | F2: MV 4 • GW | G2: 5 | H2: 2 | I2: Slow | J2: Medium | K2: midrange | L2: counters | M2: =RAND() -> 0.23320818 | N2: =RAND() -> 0.41675941 | P2: =IF($E2="","","Precon") -> Precon
A3: 1 | B3: 2021-09-24 | C3: MIC | D3: Midnight Hunt Commander | E3: Undead Unleashed | F3: MV 4 • UB | G3: 5.5 | H3: 2 | I3: Medium | J3: Medium | K3: tribal | L3: zombies | M3: =RAND() -> 0.087051363 | N3: =RAND() -> 0.025246773 | P3: =IF($E3="","","Precon") -> Precon
A4: 1 | B4: 2021-11-19 | C4: VOC | D4: Crimson Vow Commander | E4: Spirit Squadron | F4: MV 3 • WU | G4: 5.5 | H4: 2 | I4: Medium | J4: Medium | K4: tempo | L4: spirits | M4: =RAND() -> 0.61697861 | N4: =RAND() -> 0.15299407 | P4: =IF($E4="","","Precon") -> Precon
A5: 1 | B5: 2021-11-19 | C5: VOC | D5: Crimson Vow Commander | E5: Vampiric Bloodline | F5: MV 4 • BR | G5: 6 | H5: 3 | I5: Medium | J5: Medium | K5: aggro | L5: vampires | M5: =RAND() -> 0.33223399 | N5: =RAND() -> 0.039179103 | P5: =IF($E5="","","Precon") -> Precon
A6: 1 | B6: 2022-02-18 | C6: NEC | D6: Kamigawa: Neon Dynasty Commander | E6: Buckle Up | F6: MV 4 • WU | G6: 6.5 | H6: 3 | I6: Medium | J6: High | K6: value | L6: vehicles azorius artifacts | M6: =RAND() -> 0.079188853 | N6: =RAND() -> 0.77749488 | P6: =IF($E6="","","Precon") -> Precon
A7: 1 | B7: 2022-02-18 | C7: NEC | D7: Kamigawa: Neon Dynasty Commander | E7: Upgrades Unleashed | F7: MV 4 • RG | G7: 6.5 | H7: 3 | I7: Medium | J7: High | K7: aggro | L7: modified counters equipment | M7: =RAND() -> 0.83934343 | N7: =RAND() -> 0.12841002 | P7: =IF($E7="","","Precon") -> Precon
A8: 1 | B8: 2022-09-09 | C8: DMC | D8: Dominaria United Commander | E8: Legends' Legacy | F8: MV 3 • RWB | G8: 6 | H8: 3 | I8: Medium | J8: Medium | K8: value | L8: legends mardu recursion | M8: =RAND() -> 0.39543596 | N8: =RAND() -> 0.66831026 | P8: =IF($E8="","","Precon") -> Precon
A9: 1 | B9: 2022-09-09 | C9: DMC | D9: Dominaria United Commander | E9: Painbow | F9: MV 5 • WUBRG | G9: 6 | H9: 3 | I9: Medium | J9: Medium | K9: value | L9: five-color legends domain | M9: =RAND() -> 0.22795132 | N9: =RAND() -> 0.22414009 | P9: =IF($E9="","","Precon") -> Precon
A10: 1 | B10: 2022-11-18 | C10: BRC | D10: The Brothers' War Commander | E10: Mishra's Burnished Banner | F10: MV 6 • UBR | G10: 6.5 | H10: 3 | I10: Medium | J10: High | K10: value | L10: artifacts | M10: =RAND() -> 0.20912341 | N10: =RAND() -> 0.15955782 | P10: =IF($E10="","","Precon") -> Precon
A11: 1 | B11: 2022-11-18 | C11: BRC | D11: The Brothers' War Commander | E11: Urza's Iron Alliance | F11: MV 6 • WUB | G11: 6.5 | H11: 3 | I11: Medium | J11: High | K11: value | L11: artifacts | M11: =RAND() -> 0.55274181 | N11: =RAND() -> 0.027973858 | P11: =IF($E11="","","Precon") -> Precon
A12: 1 | B12: 2022-12-02 | C12: SCD | D12: Starter Commander Decks | E12: Chaos Incarnate | F12: MV 4 • BR | G12: 5 | H12: 2 | I12: Medium | J12: Medium | K12: aggro | L12: rakdos chaos | M12: =RAND() -> 0.41356165 | N12: =RAND() -> 0.48653576 | P12: =IF($E12="","","Precon") -> Precon
A13: 1 | B13: 2022-12-02 | C13: SCD | D13: Starter Commander Decks | E13: Draconic Destruction | F13: MV 6 • RG | G13: 5 | H13: 2 | I13: Medium | J13: Medium | K13: ramp | L13: dragons gruul | M13: =RAND() -> 0.20065842 | N13: =RAND() -> 0.67730521 | P13: =IF($E13="","","Precon") -> Precon
... A51: 1 | B51: 2026-01-23 | C51: ECC | D51: Lorwyn Eclipsed Commander | E51: Dance of the Elements | F51: MV 5 • WUBRG | G51: 7 | H51: 3 | I51: Medium | J51: High | K51: value | L51: elementals evoke tokens | M51: =RAND() -> 0.64486468 | N51: =RAND() -> 0.35214477 | P51: =IF($E51="","","Precon") -> Precon
P52: =IF($E52="","","Precon")
P53: =IF($E53="","","Precon")
P54: =IF($E54="","","Precon")
P55: =IF($E55="","","Precon")
P56: =IF($E56="","","Precon")
P57: =IF($E57="","","Precon")
P58: =IF($E58="","","Precon")
P59: =IF($E59="","","Precon")
P60: =IF($E60="","","Precon")
P61: =IF($E61="","","Precon")
P62: =IF($E62="","","Precon")
P63: =IF($E63="","","Precon")
... P1000: =IF($E1000="","","Precon")

Sheet Homebrew Decks
A1: Include | B1: Release Date | C1: Code | D1: Set Name | E1: Deck Name | F1: Commander Mana | G1: Power | H1: Bracket | I1: Game Speed | J1: Threat Perception | K1: Archetype | L1: Tags | M1: Pod Rand | N1: Duel Rand | O1: Commander | P1: Deck Type | Q1: Version | R1: Upgrade From
A2: 1 | B2: 45837 | C2: HBW | D2: Homebrew | E2: Giada's Ascension | F2: MV 2 • W | G2: 6.8 | H2: 3 | I2: Medium | J2: Medium | K2: lifegain midrange | L2: angel tribal | M2: =IF($E2="","",RAND()) -> 0.70020574 | N2: =IF($E2="","",RAND()) -> 0.095197033 | O2: Giada, Font of Hope | P2: =IF($E2="","",IF($R2<>"","Upgraded Precon","Homebrew")) -> Homebrew | Q2: 1
A3: 1 | B3: 45837 | C3: HBW | D3: Homebrew | E3: Silent and Deadly | F3: MV 3 • B | G3: 7.2 | H3: 4 | I3: Medium | J3: High | K3: control | L3: assassin tribal | M3: =IF($E3="","",RAND()) -> 0.97190271 | N3: =IF($E3="","",RAND()) -> 0.57633168 | O3: Massacre Girl, Known Killer | P3: =IF($E3="","",IF($R3<>"","Upgraded Precon","Homebrew")) -> Homebrew | Q3: 1
A4: =IF($E4="","",1) -> 1 | B4: 45837 | C4: HBW | D4: Homebrew | E4: Oloro's Tribute | F4: MV 7 • WUB | G4: 7.6 | H4: 4 | I4: Medium | J4: Very High | K4: lifegain/drain | L4: combo-control | M4: =IF($E4="","",RAND()) -> 0.70642685 | N4: =IF($E4="","",RAND()) -> 0.076400018 | O4: Oloro, Ageless Ascetic | P4: =IF($E4="","",IF($R4<>"","Upgraded Precon","Homebrew")) -> Homebrew | Q4: 1
A5: =IF($E5="","",1) -> 1 | B5: 45837 | C5: HBW | D5: Homebrew | E5: Squirrel! | F5: MV 2 • BG | G5: 7.4 | H5: 4 | I5: Medium | J5: High | K5: token swarm | L5: squirrel tribal | M5: =IF($E5="","",RAND()) -> 0.45099897 | N5: =IF($E5="","",RAND()) -> 0.95766849 | O5: Chatterfang, Squirrel General | P5: =IF($E5="","",IF($R5<>"","Upgraded Precon","Homebrew")) -> Homebrew | Q5: 1
A6: =IF($E6="","",1) -> 1 | B6: 45837 | C6: HBW | D6: Homebrew | E6: Nils' Silent Throne | F6: MV 3 • W | G6: 6.9 | H6: 3 | I6: Slow | J6: High | K6: tax/control | L6: pillowfort | M6: =IF($E6="","",RAND()) -> 0.21529422 | N6: =IF($E6="","",RAND()) -> 0.7562425 | O6: Nils, Discipline Enforcer | P6: =IF($E6="","",IF($R6<>"","Upgraded Precon","Homebrew")) -> Homebrew | Q6: 1
A7: =IF($E7="","",1) -> 1 | B7: 45837 | C7: HBW | D7: Homebrew | E7: The GOAT | F7: MV 9 • WUBRG | G7: 7.3 | H7: 4 | I7: Medium | J7: High | K7: combat/damage triggers | L7: dragon tribal | M7: =IF($E7="","",RAND()) -> 0.36336863 | N7: =IF($E7="","",RAND()) -> 0.76782911 | O7: The Ur-Dragon | P7: =IF($E7="","",IF($R7<>"","Upgraded Precon","Homebrew")) -> Homebrew | Q7: 1
A8: =IF($E8="","",1) | M8: =IF($E8="","",RAND()) | N8: =IF($E8="","",RAND()) | P8: =IF($E8="","",IF($R8<>"","Upgraded Precon","Homebrew"))
A9: =IF($E9="","",1) | M9: =IF($E9="","",RAND()) | N9: =IF($E9="","",RAND()) | P9: =IF($E9="","",IF($R9<>"","Upgraded Precon","Homebrew"))
A10: =IF($E10="","",1) | M10: =IF($E10="","",RAND()) | N10: =IF($E10="","",RAND()) | P10: =IF($E10="","",IF($R10<>"","Upgraded Precon","Homebrew"))
A11: =IF($E11="","",1) | M11: =IF($E11="","",RAND()) | N11: =IF($E11="","",RAND()) | P11: =IF($E11="","",IF($R11<>"","Upgraded Precon","Homebrew"))
A12: =IF($E12="","",1) | M12: =IF($E12="","",RAND()) | N12: =IF($E12="","",RAND()) | P12: =IF($E12="","",IF($R12<>"","Upgraded Precon","Homebrew"))
A13: =IF($E13="","",1) | M13: =IF($E13="","",RAND()) | N13: =IF($E13="","",RAND()) | P13: =IF($E13="","",IF($R13<>"","Upgraded Precon","Homebrew"))
A14: =IF($E14="","",1) | M14: =IF($E14="","",RAND()) | N14: =IF($E14="","",RAND()) | P14: =IF($E14="","",IF($R14<>"","Upgraded Precon","Homebrew"))
A15: =IF($E15="","",1) | M15: =IF($E15="","",RAND()) | N15: =IF($E15="","",RAND()) | P15: =IF($E15="","",IF($R15<>"","Upgraded Precon","Homebrew"))
A16: =IF($E16="","",1) | M16: =IF($E16="","",RAND()) | N16: =IF($E16="","",RAND()) | P16: =IF($E16="","",IF($R16<>"","Upgraded Precon","Homebrew"))
A17: =IF($E17="","",1) | M17: =IF($E17="","",RAND()) | N17: =IF($E17="","",RAND()) | P17: =IF($E17="","",IF($R17<>"","Upgraded Precon","Homebrew"))
A18: =IF($E18="","",1) | M18: =IF($E18="","",RAND()) | N18: =IF($E18="","",RAND()) | P18: =IF($E18="","",IF($R18<>"","Upgraded Precon","Homebrew"))
A19: =IF($E19="","",1) | M19: =IF($E19="","",RAND()) | N19: =IF($E19="","",RAND()) | P19: =IF($E19="","",IF($R19<>"","Upgraded Precon","Homebrew"))
... A1000: =IF($E1000="","",1) | M1000: =IF($E1000="","",RAND()) | N1000: =IF($E1000="","",RAND()) | P1000: =IF($E1000="","",IF($R1000<>"","Upgraded Precon","Homebrew"))

Sheet Pod Builder
A1: Bracket | B1: 3 | C1: Include | D1: Deck Name | E1: Bracket | F1: Power | G1: Game Speed | H1: Random Key | I1: Eligible | J1: Pick 1 Key | K1: Pick 2 Key | L1: Pick 3 Key | M1: Pick 4 Key | N1: Deck Type | O1: Threat Perception
A2: Min Power | B2: 6 | C2: ='Precon Decks'!A2 -> 1 | D2: ='Precon Decks'!E2 -> Coven Counters | E2: ='Precon Decks'!H2 -> 2 | F2: ='Precon Decks'!G2 -> 5 | G2: ='Precon Decks'!I2 -> Slow | H2: ='Precon Decks'!M2+$B$6/1000000 -> 0.23320918 | I2: =IF(AND($C2=1,$D2<>"",$E2=$B$1,$F2>=$B$2,$F2<=$B$3,IF(LOWER($B$4)="yes",LOWER($G2)<>"fast",TRUE()),IF(LOWER($B$14)="any",TRUE(),LOWER($N2)=LOWER($B$14)),IF(LOWER($B$15)="any",TRUE(),IF(LOWER($B$15)="exclude very high",LOWER($O2)<>"very high",IF(LOWER($B$15)="low-medium only",OR(LOWER($O2)="low",LOWER($O2)="medium"),TRUE())))),1,0) -> 0 | J2: =IF($I2=1,$H2,1E+99) -> 1e+99 | K2: =IF(OR($D2=$B$8,$J2>=1E+99,AND(OR(LOWER($O2)="high",LOWER($O2)="very high"),COUNTIF($B$18,"High")+COUNTIF($B$18,"Very High")>=$B$16)),1E+99,$J2) -> 1e+99 | L2: =IF(OR($D2=$B$8,$D2=$B$9,$J2>=1E+99,AND(OR(LOWER($O2)="high",LOWER($O2)="very high"),COUNTIF($B$18:$B$19,"High")+COUNTIF($B$18:$B$19,"Very High")>=$B$16)),1E+99,$J2) -> 1e+99 | M2: =IF(OR($D2=$B$8,$D2=$B$9,$D2=$B$10,$J2>=1E+99,AND(OR(LOWER($O2)="high",LOWER($O2)="very high"),COUNTIF($B$18:$B$20,"High")+COUNTIF($B$18:$B$20,"Very High")>=$B$16)),1E+99,$J2) -> 1e+99 | N2: ='Precon Decks'!P2 -> Precon | O2: ='Precon Decks'!J2 -> Medium
A3: Max Power | B3: 7 | C3: ='Precon Decks'!A3 -> 1 | D3: ='Precon Decks'!E3 -> Undead Unleashed | E3: ='Precon Decks'!H3 -> 2 | F3: ='Precon Decks'!G3 -> 5.5 | G3: ='Precon Decks'!I3 -> Medium | H3: ='Precon Decks'!M3+$B$6/1000000 -> 0.087052363 | I3: =IF(AND($C3=1,$D3<>"",$E3=$B$1,$F3>=$B$2,$F3<=$B$3,IF(LOWER($B$4)="yes",LOWER($G3)<>"fast",TRUE()),IF(LOWER($B$14)="any",TRUE(),LOWER($N3)=LOWER($B$14)),IF(LOWER($B$15)="any",TRUE(),IF(LOWER($B$15)="exclude very high",LOWER($O3)<>"very high",IF(LOWER($B$15)="low-medium only",OR(LOWER($O3)="low",LOWER($O3)="medium"),TRUE())))),1,0) -> 0 | J3: =IF($I3=1,$H3,1E+99) -> 1e+99 | K3: =IF(OR($D3=$B$8,$J3>=1E+99,AND(OR(LOWER($O3)="high",LOWER($O3)="very high"),COUNTIF($B$18,"High")+COUNTIF($B$18,"Very High")>=$B$16)),1E+99,$J3) -> 1e+99 | L3: =IF(OR($D3=$B$8,$D3=$B$9,$J3>=1E+99,AND(OR(LOWER($O3)="high",LOWER($O3)="very high"),COUNTIF($B$18:$B$19,"High")+COUNTIF($B$18:$B$19,"Very High")>=$B$16)),1E+99,$J3) -> 1e+99 | M3: =IF(OR($D3=$B$8,$D3=$B$9,$D3=$B$10,$J3>=1E+99,AND(OR(LOWER($O3)="high",LOWER($O3)="very high"),COUNTIF($B$18:$B$20,"High")+COUNTIF($B$18:$B$20,"Very High")>=$B$16)),1E+99,$J3) -> 1e+99 | N3: ='Precon Decks'!P3 -> Precon | O3: ='Precon Decks'!J3 -> Medium
A4: Avoid Fast (yes/no) | B4: no | C4: ='Precon Decks'!A4 -> 1 | D4: ='Precon Decks'!E4 -> Spirit Squadron | E4: ='Precon Decks'!H4 -> 2 | F4: ='Precon Decks'!G4 -> 5.5 | G4: ='Precon Decks'!I4 -> Medium | H4: ='Precon Decks'!M4+$B$6/1000000 -> 0.61697961 | I4: =IF(AND($C4=1,$D4<>"",$E4=$B$1,$F4>=$B$2,$F4<=$B$3,IF(LOWER($B$4)="yes",LOWER($G4)<>"fast",TRUE()),IF(LOWER($B$14)="any",TRUE(),LOWER($N4)=LOWER($B$14)),IF(LOWER($B$15)="any",TRUE(),IF(LOWER($B$15)="exclude very high",LOWER($O4)<>"very high",IF(LOWER($B$15)="low-medium only",OR(LOWER($O4)="low",LOWER($O4)="medium"),TRUE())))),1,0) -> 0 | J4: =IF($I4=1,$H4,1E+99) -> 1e+99 | K4: =IF(OR($D4=$B$8,$J4>=1E+99,AND(OR(LOWER($O4)="high",LOWER($O4)="very high"),COUNTIF($B$18,"High")+COUNTIF($B$18,"Very High")>=$B$16)),1E+99,$J4) -> 1e+99 | L4: =IF(OR($D4=$B$8,$D4=$B$9,$J4>=1E+99,AND(OR(LOWER($O4)="high",LOWER($O4)="very high"),COUNTIF($B$18:$B$19,"High")+COUNTIF($B$18:$B$19,"Very High")>=$B$16)),1E+99,$J4) -> 1e+99 | M4: =IF(OR($D4=$B$8,$D4=$B$9,$D4=$B$10,$J4>=1E+99,AND(OR(LOWER($O4)="high",LOWER($O4)="very high"),COUNTIF($B$18:$B$20,"High")+COUNTIF($B$18:$B$20,"Very High")>=$B$16)),1E+99,$J4) -> 1e+99 | N4: ='Precon Decks'!P4 -> Precon | O4: ='Precon Decks'!J4 -> Medium
A5: Pod Size (2-4) | B5: 4 | C5: ='Precon Decks'!A5 -> 1 | D5: ='Precon Decks'!E5 -> Vampiric Bloodline | E5: ='Precon Decks'!H5 -> 3 | F5: ='Precon Decks'!G5 -> 6 | G5: ='Precon Decks'!I5 -> Medium | H5: ='Precon Decks'!M5+$B$6/1000000 -> 0.33223499 | I5: =IF(AND($C5=1,$D5<>"",$E5=$B$1,$F5>=$B$2,$F5<=$B$3,IF(LOWER($B$4)="yes",LOWER($G5)<>"fast",TRUE()),IF(LOWER($B$14)="any",TRUE(),LOWER($N5)=LOWER($B$14)),IF(LOWER($B$15)="any",TRUE(),IF(LOWER($B$15)="exclude very high",LOWER($O5)<>"very high",IF(LOWER($B$15)="low-medium only",OR(LOWER($O5)="low",LOWER($O5)="medium"),TRUE())))),1,0) -> 1 | J5: =IF($I5=1,$H5,1E+99) -> 0.33223499 | K5: =IF(OR($D5=$B$8,$J5>=1E+99,AND(OR(LOWER($O5)="high",LOWER($O5)="very high"),COUNTIF($B$18,"High")+COUNTIF($B$18,"Very High")>=$B$16)),1E+99,$J5) -> 0.33223499 | L5: =IF(OR($D5=$B$8,$D5=$B$9,$J5>=1E+99,AND(OR(LOWER($O5)="high",LOWER($O5)="very high"),COUNTIF($B$18:$B$19,"High")+COUNTIF($B$18:$B$19,"Very High")>=$B$16)),1E+99,$J5) -> 0.33223499 | M5: =IF(OR($D5=$B$8,$D5=$B$9,$D5=$B$10,$J5>=1E+99,AND(OR(LOWER($O5)="high",LOWER($O5)="very high"),COUNTIF($B$18:$B$20,"High")+COUNTIF($B$18:$B$20,"Very High")>=$B$16)),1E+99,$J5) -> 0.33223499 | N5: ='Precon Decks'!P5 -> Precon | O5: ='Precon Decks'!J5 -> Medium
A6: Reroll | B6: 1 | C6: ='Precon Decks'!A6 -> 1 | D6: ='Precon Decks'!E6 -> Buckle Up | E6: ='Precon Decks'!H6 -> 3 | F6: ='Precon Decks'!G6 -> 6.5 | G6: ='Precon Decks'!I6 -> Medium | H6: ='Precon Decks'!M6+$B$6/1000000 -> 0.079189853 | I6: =IF(AND($C6=1,$D6<>"",$E6=$B$1,$F6>=$B$2,$F6<=$B$3,IF(LOWER($B$4)="yes",LOWER($G6)<>"fast",TRUE()),IF(LOWER($B$14)="any",TRUE(),LOWER($N6)=LOWER($B$14)),IF(LOWER($B$15)="any",TRUE(),IF(LOWER($B$15)="exclude very high",LOWER($O6)<>"very high",IF(LOWER($B$15)="low-medium only",OR(LOWER($O6)="low",LOWER($O6)="medium"),TRUE())))),1,0) -> 1 | J6: =IF($I6=1,$H6,1E+99) -> 0.079189853 | K6: =IF(OR($D6=$B$8,$J6>=1E+99,AND(OR(LOWER($O6)="high",LOWER($O6)="very high"),COUNTIF($B$18,"High")+COUNTIF($B$18,"Very High")>=$B$16)),1E+99,$J6) -> 1e+99 | L6: =IF(OR($D6=$B$8,$D6=$B$9,$J6>=1E+99,AND(OR(LOWER($O6)="high",LOWER($O6)="very high"),COUNTIF($B$18:$B$19,"High")+COUNTIF($B$18:$B$19,"Very High")>=$B$16)),1E+99,$J6) -> 1e+99 | M6: =IF(OR($D6=$B$8,$D6=$B$9,$D6=$B$10,$J6>=1E+99,AND(OR(LOWER($O6)="high",LOWER($O6)="very high"),COUNTIF($B$18:$B$20,"High")+COUNTIF($B$18:$B$20,"Very High")>=$B$16)),1E+99,$J6) -> 1e+99 | N6: ='Precon Decks'!P6 -> Precon | O6: ='Precon Decks'!J6 -> High
C7: ='Precon Decks'!A7 -> 1 | D7: ='Precon Decks'!E7 -> Upgrades Unleashed | E7: ='Precon Decks'!H7 -> 3 | F7: ='Precon Decks'!G7 -> 6.5 | G7: ='Precon Decks'!I7 -> Medium | H7: ='Precon Decks'!M7+$B$6/1000000 -> 0.83934443 | I7: =IF(AND($C7=1,$D7<>"",$E7=$B$1,$F7>=$B$2,$F7<=$B$3,IF(LOWER($B$4)="yes",LOWER($G7)<>"fast",TRUE()),IF(LOWER($B$14)="any",TRUE(),LOWER($N7)=LOWER($B$14)),IF(LOWER($B$15)="any",TRUE(),IF(LOWER($B$15)="exclude very high",LOWER($O7)<>"very high",IF(LOWER($B$15)="low-medium only",OR(LOWER($O7)="low",LOWER($O7)="medium"),TRUE())))),1,0) -> 1 | J7: =IF($I7=1,$H7,1E+99) -> 0.83934443 | K7: =IF(OR($D7=$B$8,$J7>=1E+99,AND(OR(LOWER($O7)="high",LOWER($O7)="very high"),COUNTIF($B$18,"High")+COUNTIF($B$18,"Very High")>=$B$16)),1E+99,$J7) -> 0.83934443 | L7: =IF(OR($D7=$B$8,$D7=$B$9,$J7>=1E+99,AND(OR(LOWER($O7)="high",LOWER($O7)="very high"),COUNTIF($B$18:$B$19,"High")+COUNTIF($B$18:$B$19,"Very High")>=$B$16)),1E+99,$J7) -> 0.83934443 | M7: =IF(OR($D7=$B$8,$D7=$B$9,$D7=$B$10,$J7>=1E+99,AND(OR(LOWER($O7)="high",LOWER($O7)="very high"),COUNTIF($B$18:$B$20,"High")+COUNTIF($B$18:$B$20,"Very High")>=$B$16)),1E+99,$J7) -> 1e+99 | N7: ='Precon Decks'!P7 -> Precon | O7: ='Precon Decks'!J7 -> High
A8: Random Balanced Pod | B8: {=IFERROR(INDEX($D$2:$D$1999, MATCH(SMALL($J$2:$J$1999,1), $J$2:$J$1999,0)), "")} -> Buckle Up | C8: ='Precon Decks'!A8 -> 1 | D8: ='Precon Decks'!E8 -> Legends' Legacy | E8: ='Precon Decks'!H8 -> 3 | F8: ='Precon Decks'!G8 -> 6 | G8: ='Precon Decks'!I8 -> Medium | H8: ='Precon Decks'!M8+$B$6/1000000 -> 0.39543695 | I8: =IF(AND($C8=1,$D8<>"",$E8=$B$1,$F8>=$B$2,$F8<=$B$3,IF(LOWER($B$4)="yes",LOWER($G8)<>"fast",TRUE()),IF(LOWER($B$14)="any",TRUE(),LOWER($N8)=LOWER($B$14)),IF(LOWER($B$15)="any",TRUE(),IF(LOWER($B$15)="exclude very high",LOWER($O8)<>"very high",IF(LOWER($B$15)="low-medium only",OR(LOWER($O8)="low",LOWER($O8)="medium"),TRUE())))),1,0) -> 1 | J8: =IF($I8=1,$H8,1E+99) -> 0.39543695 | K8: =IF(OR($D8=$B$8,$J8>=1E+99,AND(OR(LOWER($O8)="high",LOWER($O8)="very high"),COUNTIF($B$18,"High")+COUNTIF($B$18,"Very High")>=$B$16)),1E+99,$J8) -> 0.39543695 | L8: =IF(OR($D8=$B$8,$D8=$B$9,$J8>=1E+99,AND(OR(LOWER($O8)="high",LOWER($O8)="very high"),COUNTIF($B$18:$B$19,"High")+COUNTIF($B$18:$B$19,"Very High")>=$B$16)),1E+99,$J8) -> 0.39543695 | M8: =IF(OR($D8=$B$8,$D8=$B$9,$D8=$B$10,$J8>=1E+99,AND(OR(LOWER($O8)="high",LOWER($O8)="very high"),COUNTIF($B$18:$B$20,"High")+COUNTIF($B$18:$B$20,"Very High")>=$B$16)),1E+99,$J8) -> 0.39543695 | N8: ='Precon Decks'!P8 -> Precon | O8: ='Precon Decks'!J8 -> Medium
B9: {=IF($B$5<2,"",IFERROR(INDEX($D$2:$D$1999, MATCH(SMALL($K$2:$K$1999,1), $K$2:$K$1999,0)), ""))} -> Jump Scare! | C9: ='Precon Decks'!A9 -> 1 | D9: ='Precon Decks'!E9 -> Painbow | E9: ='Precon Decks'!H9 -> 3 | F9: ='Precon Decks'!G9 -> 6 | G9: ='Precon Decks'!I9 -> Medium | H9: ='Precon Decks'!M9+$B$6/1000000 -> 0.22795232 | I9: =IF(AND($C9=1,$D9<>"",$E9=$B$1,$F9>=$B$2,$F9<=$B$3,IF(LOWER($B$4)="yes",LOWER($G9)<>"fast",TRUE()),IF(LOWER($B$14)="any",TRUE(),LOWER($N9)=LOWER($B$14)),IF(LOWER($B$15)="any",TRUE(),IF(LOWER($B$15)="exclude very high",LOWER($O9)<>"very high",IF(LOWER($B$15)="low-medium only",OR(LOWER($O9)="low",LOWER($O9)="medium"),TRUE())))),1,0) -> 1 | J9: =IF($I9=1,$H9,1E+99) -> 0.22795232 | K9: =IF(OR($D9=$B$8,$J9>=1E+99,AND(OR(LOWER($O9)="high",LOWER($O9)="very high"),COUNTIF($B$18,"High")+COUNTIF($B$18,"Very High")>=$B$16)),1E+99,$J9) -> 0.22795232 | L9: =IF(OR($D9=$B$8,$D9=$B$9,$J9>=1E+99,AND(OR(LOWER($O9)="high",LOWER($O9)="very high"),COUNTIF($B$18:$B$19,"High")+COUNTIF($B$18:$B$19,"Very High")>=$B$16)),1E+99,$J9) -> 0.22795232 | M9: =IF(OR($D9=$B$8,$D9=$B$9,$D9=$B$10,$J9>=1E+99,AND(OR(LOWER($O9)="high",LOWER($O9)="very high"),COUNTIF($B$18:$B$20,"High")+COUNTIF($B$18:$B$20,"Very High")>=$B$16)),1E+99,$J9) -> 0.22795232 | N9: ='Precon Decks'!P9 -> Precon | O9: ='Precon Decks'!J9 -> Medium
B10: {=IF($B$5<3,"",IFERROR(INDEX($D$2:$D$1999, MATCH(SMALL($L$2:$L$1999,1), $L$2:$L$1999,0)), ""))} -> Paradox Power | C10: ='Precon Decks'!A10 -> 1 | D10: ='Precon Decks'!E10 -> Mishra's Burnished Banner | E10: ='Precon Decks'!H10 -> 3 | F10: ='Precon Decks'!G10 -> 6.5 | G10: ='Precon Decks'!I10 -> Medium | H10: ='Precon Decks'!M10+$B$6/1000000 -> 0.20912441 | I10: =IF(AND($C10=1,$D10<>"",$E10=$B$1,$F10>=$B$2,$F10<=$B$3,IF(LOWER($B$4)="yes",LOWER($G10)<>"fast",TRUE()),IF(LOWER($B$14)="any",TRUE(),LOWER($N10)=LOWER($B$14)),IF(LOWER($B$15)="any",TRUE(),IF(LOWER($B$15)="exclude very high",LOWER($O10)<>"very high",IF(LOWER($B$15)="low-medium only",OR(LOWER($O10)="low",LOWER($O10)="medium"),TRUE())))),1,0) -> 1 | J10: =IF($I10=1,$H10,1E+99) -> 0.20912441 | K10: =IF(OR($D10=$B$8,$J10>=1E+99,AND(OR(LOWER($O10)="high",LOWER($O10)="very high"),COUNTIF($B$18,"High")+COUNTIF($B$18,"Very High")>=$B$16)),1E+99,$J10) -> 0.20912441 | L10: =IF(OR($D10=$B$8,$D10=$B$9,$J10>=1E+99,AND(OR(LOWER($O10)="high",LOWER($O10)="very high"),COUNTIF($B$18:$B$19,"High")+COUNTIF($B$18:$B$19,"Very High")>=$B$16)),1E+99,$J10) -> 0.20912441 | M10: =IF(OR($D10=$B$8,$D10=$B$9,$D10=$B$10,$J10>=1E+99,AND(OR(LOWER($O10)="high",LOWER($O10)="very high"),COUNTIF($B$18:$B$20,"High")+COUNTIF($B$18:$B$20,"Very High")>=$B$16)),1E+99,$J10) -> 1e+99 | N10: ='Precon Decks'!P10 -> Precon | O10: ='Precon Decks'!J10 -> High
B11: {=IF($B$5<4,"",IFERROR(INDEX($D$2:$D$1999, MATCH(SMALL($M$2:$M$1999,1), $M$2:$M$1999,0)), ""))} -> Painbow | C11: ='Precon Decks'!A11 -> 1 | D11: ='Precon Decks'!E11 -> Urza's Iron Alliance | E11: ='Precon Decks'!H11 -> 3 | F11: ='Precon Decks'!G11 -> 6.5 | G11: ='Precon Decks'!I11 -> Medium | H11: ='Precon Decks'!M11+$B$6/1000000 -> 0.55274281 | I11: =IF(AND($C11=1,$D11<>"",$E11=$B$1,$F11>=$B$2,$F11<=$B$3,IF(LOWER($B$4)="yes",LOWER($G11)<>"fast",TRUE()),IF(LOWER($B$14)="any",TRUE(),LOWER($N11)=LOWER($B$14)),IF(LOWER($B$15)="any",TRUE(),IF(LOWER($B$15)="exclude very high",LOWER($O11)<>"very high",IF(LOWER($B$15)="low-medium only",OR(LOWER($O11)="low",LOWER($O11)="medium"),TRUE())))),1,0) -> 1 | J11: =IF($I11=1,$H11,1E+99) -> 0.55274281 | K11: =IF(OR($D11=$B$8,$J11>=1E+99,AND(OR(LOWER($O11)="high",LOWER($O11)="very high"),COUNTIF($B$18,"High")+COUNTIF($B$18,"Very High")>=$B$16)),1E+99,$J11) -> 0.55274281 | L11: =IF(OR($D11=$B$8,$D11=$B$9,$J11>=1E+99,AND(OR(LOWER($O11)="high",LOWER($O11)="very high"),COUNTIF($B$18:$B$19,"High")+COUNTIF($B$18:$B$19,"Very High")>=$B$16)),1E+99,$J11) -> 0.55274281 | M11: =IF(OR($D11=$B$8,$D11=$B$9,$D11=$B$10,$J11>=1E+99,AND(OR(LOWER($O11)="high",LOWER($O11)="very high"),COUNTIF($B$18:$B$20,"High")+COUNTIF($B$18:$B$20,"Very High")>=$B$16)),1E+99,$J11) -> 1e+99 | N11: ='Precon Decks'!P11 -> Precon | O11: ='Precon Decks'!J11 -> High
A12: Eligible deck count | B12: =COUNTIF($I$2:$I$1999,1) -> 34 | C12: ='Precon Decks'!A12 -> 1 | D12: ='Precon Decks'!E12 -> Chaos Incarnate | E12: ='Precon Decks'!H12 -> 2 | F12: ='Precon Decks'!G12 -> 5 | G12: ='Precon Decks'!I12 -> Medium | H12: ='Precon Decks'!M12+$B$6/1000000 -> 0.41356265 | I12: =IF(AND($C12=1,$D12<>"",$E12=$B$1,$F12>=$B$2,$F12<=$B$3,IF(LOWER($B$4)="yes",LOWER($G12)<>"fast",TRUE()),IF(LOWER($B$14)="any",TRUE(),LOWER($N12)=LOWER($B$14)),IF(LOWER($B$15)="any",TRUE(),IF(LOWER($B$15)="exclude very high",LOWER($O12)<>"very high",IF(LOWER($B$15)="low-medium only",OR(LOWER($O12)="low",LOWER($O12)="medium"),TRUE())))),1,0) -> 0 | J12: =IF($I12=1,$H12,1E+99) -> 1e+99 | K12: =IF(OR($D12=$B$8,$J12>=1E+99,AND(OR(LOWER($O12)="high",LOWER($O12)="very high"),COUNTIF($B$18,"High")+COUNTIF($B$18,"Very High")>=$B$16)),1E+99,$J12) -> 1e+99 | L12: =IF(OR($D12=$B$8,$D12=$B$9,$J12>=1E+99,AND(OR(LOWER($O12)="high",LOWER($O12)="very high"),COUNTIF($B$18:$B$19,"High")+COUNTIF($B$18:$B$19,"Very High")>=$B$16)),1E+99,$J12) -> 1e+99 | M12: =IF(OR($D12=$B$8,$D12=$B$9,$D12=$B$10,$J12>=1E+99,AND(OR(LOWER($O12)="high",LOWER($O12)="very high"),COUNTIF($B$18:$B$20,"High")+COUNTIF($B$18:$B$20,"Very High")>=$B$16)),1E+99,$J12) -> 1e+99 | N12: ='Precon Decks'!P12 -> Precon | O12: ='Precon Decks'!J12 -> Medium
A13: Pool | B13: =IF(COUNTIF('Homebrew Decks'!$A$2:$A$1000,1)>0,"Precons + Homebrews","Precons only") -> Precons + Homebrews | C13: ='Precon Decks'!A13 -> 1 | D13: ='Precon Decks'!E13 -> Draconic Destruction | E13: ='Precon Decks'!H13 -> 2 | F13: ='Precon Decks'!G13 -> 5 | G13: ='Precon Decks'!I13 -> Medium | H13: ='Precon Decks'!M13+$B$6/1000000 -> 0.20065942 | I13: =IF(AND($C13=1,$D13<>"",$E13=$B$1,$F13>=$B$2,$F13<=$B$3,IF(LOWER($B$4)="yes",LOWER($G13)<>"fast",TRUE()),IF(LOWER($B$14)="any",TRUE(),LOWER($N13)=LOWER($B$14)),IF(LOWER($B$15)="any",TRUE(),IF(LOWER($B$15)="exclude very high",LOWER($O13)<>"very high",IF(LOWER($B$15)="low-medium only",OR(LOWER($O13)="low",LOWER($O13)="medium"),TRUE())))),1,0) -> 0 | J13: =IF($I13=1,$H13,1E+99) -> 1e+99 | K13: =IF(OR($D13=$B$8,$J13>=1E+99,AND(OR(LOWER($O13)="high",LOWER($O13)="very high"),COUNTIF($B$18,"High")+COUNTIF($B$18,"Very High")>=$B$16)),1E+99,$J13) -> 1e+99 | L13: =IF(OR($D13=$B$8,$D13=$B$9,$J13>=1E+99,AND(OR(LOWER($O13)="high",LOWER($O13)="very high"),COUNTIF($B$18:$B$19,"High")+COUNTIF($B$18:$B$19,"Very High")>=$B$16)),1E+99,$J13) -> 1e+99 | M13: =IF(OR($D13=$B$8,$D13=$B$9,$D13=$B$10,$J13>=1E+99,AND(OR(LOWER($O13)="high",LOWER($O13)="very high"),COUNTIF($B$18:$B$20,"High")+COUNTIF($B$18:$B$20,"Very High")>=$B$16)),1E+99,$J13) -> 1e+99 | N13: ='Precon Decks'!P13 -> Precon | O13: ='Precon Decks'!J13 -> Medium
A14: Deck Type | B14: any | C14: ='Precon Decks'!A14 -> 1 | D14: ='Precon Decks'!E14 -> First Flight | E14: ='Precon Decks'!H14 -> 2 | F14: ='Precon Decks'!G14 -> 4.5 | G14: ='Precon Decks'!I14 -> Medium | H14: ='Precon Decks'!M14+$B$6/1000000 -> 0.0076110767 | I14: =IF(AND($C14=1,$D14<>"",$E14=$B$1,$F14>=$B$2,$F14<=$B$3,IF(LOWER($B$4)="yes",LOWER($G14)<>"fast",TRUE()),IF(LOWER($B$14)="any",TRUE(),LOWER($N14)=LOWER($B$14)),IF(LOWER($B$15)="any",TRUE(),IF(LOWER($B$15)="exclude very high",LOWER($O14)<>"very high",IF(LOWER($B$15)="low-medium only",OR(LOWER($O14)="low",LOWER($O14)="medium"),TRUE())))),1,0) -> 0 | J14: =IF($I14=1,$H14,1E+99) -> 1e+99 | K14: =IF(OR($D14=$B$8,$J14>=1E+99,AND(OR(LOWER($O14)="high",LOWER($O14)="very high"),COUNTIF($B$18,"High")+COUNTIF($B$18,"Very High")>=$B$16)),1E+99,$J14) -> 1e+99 | L14: =IF(OR($D14=$B$8,$D14=$B$9,$J14>=1E+99,AND(OR(LOWER($O14)="high",LOWER($O14)="very high"),COUNTIF($B$18:$B$19,"High")+COUNTIF($B$18:$B$19,"Very High")>=$B$16)),1E+99,$J14) -> 1e+99 | M14: =IF(OR($D14=$B$8,$D14=$B$9,$D14=$B$10,$J14>=1E+99,AND(OR(LOWER($O14)="high",LOWER($O14)="very high"),COUNTIF($B$18:$B$20,"High")+COUNTIF($B$18:$B$20,"Very High")>=$B$16)),1E+99,$J14) -> 1e+99 | N14: ='Precon Decks'!P14 -> Precon | O14: ='Precon Decks'!J14 -> Medium
A15: Threat Filter | B15: any | C15: ='Precon Decks'!A15 -> 1 | D15: ='Precon Decks'!E15 -> Grave Danger | E15: ='Precon Decks'!H15 -> 2 | F15: ='Precon Decks'!G15 -> 5 | G15: ='Precon Decks'!I15 -> Medium | H15: ='Precon Decks'!M15+$B$6/1000000 -> 0.8705699 | I15: =IF(AND($C15=1,$D15<>"",$E15=$B$1,$F15>=$B$2,$F15<=$B$3,IF(LOWER($B$4)="yes",LOWER($G15)<>"fast",TRUE()),IF(LOWER($B$14)="any",TRUE(),LOWER($N15)=LOWER($B$14)),IF(LOWER($B$15)="any",TRUE(),IF(LOWER($B$15)="exclude very high",LOWER($O15)<>"very high",IF(LOWER($B$15)="low-medium only",OR(LOWER($O15)="low",LOWER($O15)="medium"),TRUE())))),1,0) -> 0 | J15: =IF($I15=1,$H15,1E+99) -> 1e+99 | K15: =IF(OR($D15=$B$8,$J15>=1E+99,AND(OR(LOWER($O15)="high",LOWER($O15)="very high"),COUNTIF($B$18,"High")+COUNTIF($B$18,"Very High")>=$B$16)),1E+99,$J15) -> 1e+99 | L15: =IF(OR($D15=$B$8,$D15=$B$9,$J15>=1E+99,AND(OR(LOWER($O15)="high",LOWER($O15)="very high"),COUNTIF($B$18:$B$19,"High")+COUNTIF($B$18:$B$19,"Very High")>=$B$16)),1E+99,$J15) -> 1e+99 | M15: =IF(OR($D15=$B$8,$D15=$B$9,$D15=$B$10,$J15>=1E+99,AND(OR(LOWER($O15)="high",LOWER($O15)="very high"),COUNTIF($B$18:$B$20,"High")+COUNTIF($B$18:$B$20,"Very High")>=$B$16)),1E+99,$J15) -> 1e+99 | N15: ='Precon Decks'!P15 -> Precon | O15: ='Precon Decks'!J15 -> Medium
A16: Max High Threat | B16: 2 | C16: ='Precon Decks'!A16 -> 1 | D16: ='Precon Decks'!E16 -> Token Triumph | E16: ='Precon Decks'!H16 -> 2 | F16: ='Precon Decks'!G16 -> 4.5 | G16: ='Precon Decks'!I16 -> Medium | H16: ='Precon Decks'!M16+$B$6/1000000 -> 0.70489531 | I16: =IF(AND($C16=1,$D16<>"",$E16=$B$1,$F16>=$B$2,$F16<=$B$3,IF(LOWER($B$4)="yes",LOWER($G16)<>"fast",TRUE()),IF(LOWER($B$14)="any",TRUE(),LOWER($N16)=LOWER($B$14)),IF(LOWER($B$15)="any",TRUE(),IF(LOWER($B$15)="exclude very high",LOWER($O16)<>"very high",IF(LOWER($B$15)="low-medium only",OR(LOWER($O16)="low",LOWER($O16)="medium"),TRUE())))),1,0) -> 0 | J16: =IF($I16=1,$H16,1E+99) -> 1e+99 | K16: =IF(OR($D16=$B$8,$J16>=1E+99,AND(OR(LOWER($O16)="high",LOWER($O16)="very high"),COUNTIF($B$18,"High")+COUNTIF($B$18,"Very High")>=$B$16)),1E+99,$J16) -> 1e+99 | L16: =IF(OR($D16=$B$8,$D16=$B$9,$J16>=1E+99,AND(OR(LOWER($O16)="high",LOWER($O16)="very high"),COUNTIF($B$18:$B$19,"High")+COUNTIF($B$18:$B$19,"Very High")>=$B$16)),1E+99,$J16) -> 1e+99 | M16: =IF(OR($D16=$B$8,$D16=$B$9,$D16=$B$10,$J16>=1E+99,AND(OR(LOWER($O16)="high",LOWER($O16)="very high"),COUNTIF($B$18:$B$20,"High")+COUNTIF($B$18:$B$20,"Very High")>=$B$16)),1E+99,$J16) -> 1e+99 | N16: ='Precon Decks'!P16 -> Precon | O16: ='Precon Decks'!J16 -> Medium
C17: ='Precon Decks'!A17 -> 1 | D17: ='Precon Decks'!E17 -> Corrupting Influence | E17: ='Precon Decks'!H17 -> 3 | F17: ='Precon Decks'!G17 -> 6.5 | G17: ='Precon Decks'!I17 -> Fast | H17: ='Precon Decks'!M17+$B$6/1000000 -> 0.42432634 | I17: =IF(AND($C17=1,$D17<>"",$E17=$B$1,$F17>=$B$2,$F17<=$B$3,IF(LOWER($B$4)="yes",LOWER($G17)<>"fast",TRUE()),IF(LOWER($B$14)="any",TRUE(),LOWER($N17)=LOWER($B$14)),IF(LOWER($B$15)="any",TRUE(),IF(LOWER($B$15)="exclude very high",LOWER($O17)<>"very high",IF(LOWER($B$15)="low-medium only",OR(LOWER($O17)="low",LOWER($O17)="medium"),TRUE())))),1,0) -> 1 | J17: =IF($I17=1,$H17,1E+99) -> 0.42432634 | K17: =IF(OR($D17=$B$8,$J17>=1E+99,AND(OR(LOWER($O17)="high",LOWER($O17)="very high"),COUNTIF($B$18,"High")+COUNTIF($B$18,"Very High")>=$B$16)),1E+99,$J17) -> 0.42432634 | L17: =IF(OR($D17=$B$8,$D17=$B$9,$J17>=1E+99,AND(OR(LOWER($O17)="high",LOWER($O17)="very high"),COUNTIF($B$18:$B$19,"High")+COUNTIF($B$18:$B$19,"Very High")>=$B$16)),1E+99,$J17) -> 0.42432634 | M17: =IF(OR($D17=$B$8,$D17=$B$9,$D17=$B$10,$J17>=1E+99,AND(OR(LOWER($O17)="high",LOWER($O17)="very high"),COUNTIF($B$18:$B$20,"High")+COUNTIF($B$18:$B$20,"Very High")>=$B$16)),1E+99,$J17) -> 1e+99 | N17: ='Precon Decks'!P17 -> Precon | O17: ='Precon Decks'!J17 -> High
A18: Pick 1 Threat | B18: {=IFERROR(INDEX($O$2:$O$1999, MATCH($B$8,$D$2:$D$1999,0)), "")} -> High | C18: ='Precon Decks'!A18 -> 1 | D18: ='Precon Decks'!E18 -> Rebellion Rising | E18: ='Precon Decks'!H18 -> 2 | F18: ='Precon Decks'!G18 -> 5.5 | G18: ='Precon Decks'!I18 -> Medium | H18: ='Precon Decks'!M18+$B$6/1000000 -> 0.1557384 | I18: =IF(AND($C18=1,$D18<>"",$E18=$B$1,$F18>=$B$2,$F18<=$B$3,IF(LOWER($B$4)="yes",LOWER($G18)<>"fast",TRUE()),IF(LOWER($B$14)="any",TRUE(),LOWER($N18)=LOWER($B$14)),IF(LOWER($B$15)="any",TRUE(),IF(LOWER($B$15)="exclude very high",LOWER($O18)<>"very high",IF(LOWER($B$15)="low-medium only",OR(LOWER($O18)="low",LOWER($O18)="medium"),TRUE())))),1,0) -> 0 | J18: =IF($I18=1,$H18,1E+99) -> 1e+99 | K18: =IF(OR($D18=$B$8,$J18>=1E+99,AND(OR(LOWER($O18)="high",LOWER($O18)="very high"),COUNTIF($B$18,"High")+COUNTIF($B$18,"Very High")>=$B$16)),1E+99,$J18) -> 1e+99 | L18: =IF(OR($D18=$B$8,$D18=$B$9,$J18>=1E+99,AND(OR(LOWER($O18)="high",LOWER($O18)="very high"),COUNTIF($B$18:$B$19,"High")+COUNTIF($B$18:$B$19,"Very High")>=$B$16)),1E+99,$J18) -> 1e+99 | M18: =IF(OR($D18=$B$8,$D18=$B$9,$D18=$B$10,$J18>=1E+99,AND(OR(LOWER($O18)="high",LOWER($O18)="very high"),COUNTIF($B$18:$B$20,"High")+COUNTIF($B$18:$B$20,"Very High")>=$B$16)),1E+99,$J18) -> 1e+99 | N18: ='Precon Decks'!P18 -> Precon | O18: ='Precon Decks'!J18 -> Medium
A19: Pick 2 Threat | B19: {=IFERROR(INDEX($O$2:$O$1999, MATCH($B$9,$D$2:$D$1999,0)), "")} -> Medium | C19: ='Precon Decks'!A19 -> 1 | D19: ='Precon Decks'!E19 -> Call for Backup | E19: ='Precon Decks'!H19 -> 3 | F19: ='Precon Decks'!G19 -> 6 | G19: ='Precon Decks'!I19 -> Medium | H19: ='Precon Decks'!M19+$B$6/1000000 -> 0.7139288 | I19: =IF(AND($C19=1,$D19<>"",$E19=$B$1,$F19>=$B$2,$F19<=$B$3,IF(LOWER($B$4)="yes",LOWER($G19)<>"fast",TRUE()),IF(LOWER($B$14)="any",TRUE(),LOWER($N19)=LOWER($B$14)),IF(LOWER($B$15)="any",TRUE(),IF(LOWER($B$15)="exclude very high",LOWER($O19)<>"very high",IF(LOWER($B$15)="low-medium only",OR(LOWER($O19)="low",LOWER($O19)="medium"),TRUE())))),1,0) -> 1 | J19: =IF($I19=1,$H19,1E+99) -> 0.7139288 | K19: =IF(OR($D19=$B$8,$J19>=1E+99,AND(OR(LOWER($O19)="high",LOWER($O19)="very high"),COUNTIF($B$18,"High")+COUNTIF($B$18,"Very High")>=$B$16)),1E+99,$J19) -> 0.7139288 | L19: =IF(OR($D19=$B$8,$D19=$B$9,$J19>=1E+99,AND(OR(LOWER($O19)="high",LOWER($O19)="very high"),COUNTIF($B$18:$B$19,"High")+COUNTIF($B$18:$B$19,"Very High")>=$B$16)),1E+99,$J19) -> 0.7139288 | M19: =IF(OR($D19=$B$8,$D19=$B$9,$D19=$B$10,$J19>=1E+99,AND(OR(LOWER($O19)="high",LOWER($O19)="very high"),COUNTIF($B$18:$B$20,"High")+COUNTIF($B$18:$B$20,"Very High")>=$B$16)),1E+99,$J19) -> 0.7139288 | N19: ='Precon Decks'!P19 -> Precon | O19: ='Precon Decks'!J19 -> Medium
A20: Pick 3 Threat | B20: {=IFERROR(INDEX($O$2:$O$1999, MATCH($B$10,$D$2:$D$1999,0)), "")} -> High | C20: ='Precon Decks'!A20 -> 1 | D20: ='Precon Decks'!E20 -> Cavalry Charge | E20: ='Precon Decks'!H20 -> 4 | F20: ='Precon Decks'!G20 -> 7 | G20: ='Precon Decks'!I20 -> Medium | H20: ='Precon Decks'!M20+$B$6/1000000 -> 0.32850909 | I20: =IF(AND($C20=1,$D20<>"",$E20=$B$1,$F20>=$B$2,$F20<=$B$3,IF(LOWER($B$4)="yes",LOWER($G20)<>"fast",TRUE()),IF(LOWER($B$14)="any",TRUE(),LOWER($N20)=LOWER($B$14)),IF(LOWER($B$15)="any",TRUE(),IF(LOWER($B$15)="exclude very high",LOWER($O20)<>"very high",IF(LOWER($B$15)="low-medium only",OR(LOWER($O20)="low",LOWER($O20)="medium"),TRUE())))),1,0) -> 0 | J20: =IF($I20=1,$H20,1E+99) -> 1e+99 | K20: =IF(OR($D20=$B$8,$J20>=1E+99,AND(OR(LOWER($O20)="high",LOWER($O20)="very high"),COUNTIF($B$18,"High")+COUNTIF($B$18,"Very High")>=$B$16)),1E+99,$J20) -> 1e+99 | L20: =IF(OR($D20=$B$8,$D20=$B$9,$J20>=1E+99,AND(OR(LOWER($O20)="high",LOWER($O20)="very high"),COUNTIF($B$18:$B$19,"High")+COUNTIF($B$18:$B$19,"Very High")>=$B$16)),1E+99,$J20) -> 1e+99 | M20: =IF(OR($D20=$B$8,$D20=$B$9,$D20=$B$10,$J20>=1E+99,AND(OR(LOWER($O20)="high",LOWER($O20)="very high"),COUNTIF($B$18:$B$20,"High")+COUNTIF($B$18:$B$20,"Very High")>=$B$16)),1E+99,$J20) -> 1e+99 | N20: ='Precon Decks'!P20 -> Precon | O20: ='Precon Decks'!J20 -> High
A21: Pick 4 Threat | B21: {=IFERROR(INDEX($O$2:$O$1999, MATCH($B$11,$D$2:$D$1999,0)), "")} -> Medium | C21: ='Precon Decks'!A21 -> 1 | D21: ='Precon Decks'!E21 -> Divine Convocation | E21: ='Precon Decks'!H21 -> 2 | F21: ='Precon Decks'!G21 -> 5.5 | G21: ='Precon Decks'!I21 -> Slow | H21: ='Precon Decks'!M21+$B$6/1000000 -> 0.84982528 | I21: =IF(AND($C21=1,$D21<>"",$E21=$B$1,$F21>=$B$2,$F21<=$B$3,IF(LOWER($B$4)="yes",LOWER($G21)<>"fast",TRUE()),IF(LOWER($B$14)="any",TRUE(),LOWER($N21)=LOWER($B$14)),IF(LOWER($B$15)="any",TRUE(),IF(LOWER($B$15)="exclude very high",LOWER($O21)<>"very high",IF(LOWER($B$15)="low-medium only",OR(LOWER($O21)="low",LOWER($O21)="medium"),TRUE())))),1,0) -> 0 | J21: =IF($I21=1,$H21,1E+99) -> 1e+99 | K21: =IF(OR($D21=$B$8,$J21>=1E+99,AND(OR(LOWER($O21)="high",LOWER($O21)="very high"),COUNTIF($B$18,"High")+COUNTIF($B$18,"Very High")>=$B$16)),1E+99,$J21) -> 1e+99 | L21: =IF(OR($D21=$B$8,$D21=$B$9,$J21>=1E+99,AND(OR(LOWER($O21)="high",LOWER($O21)="very high"),COUNTIF($B$18:$B$19,"High")+COUNTIF($B$18:$B$19,"Very High")>=$B$16)),1E+99,$J21) -> 1e+99 | M21: =IF(OR($D21=$B$8,$D21=$B$9,$D21=$B$10,$J21>=1E+99,AND(OR(LOWER($O21)="high",LOWER($O21)="very high"),COUNTIF($B$18:$B$20,"High")+COUNTIF($B$18:$B$20,"Very High")>=$B$16)),1E+99,$J21) -> 1e+99 | N21: ='Precon Decks'!P21 -> Precon | O21: ='Precon Decks'!J21 -> Medium
C22: ='Precon Decks'!A22 -> 1 | D22: ='Precon Decks'!E22 -> Growing Threat | E22: ='Precon Decks'!H22 -> 3 | F22: ='Precon Decks'!G22 -> 6 | G22: ='Precon Decks'!I22 -> Medium | H22: ='Precon Decks'!M22+$B$6/1000000 -> 0.86284235 | I22: =IF(AND($C22=1,$D22<>"",$E22=$B$1,$F22>=$B$2,$F22<=$B$3,IF(LOWER($B$4)="yes",LOWER($G22)<>"fast",TRUE()),IF(LOWER($B$14)="any",TRUE(),LOWER($N22)=LOWER($B$14)),IF(LOWER($B$15)="any",TRUE(),IF(LOWER($B$15)="exclude very high",LOWER($O22)<>"very high",IF(LOWER($B$15)="low-medium only",OR(LOWER($O22)="low",LOWER($O22)="medium"),TRUE())))),1,0) -> 1 | J22: =IF($I22=1,$H22,1E+99) -> 0.86284235 | K22: =IF(OR($D22=$B$8,$J22>=1E+99,AND(OR(LOWER($O22)="high",LOWER($O22)="very high"),COUNTIF($B$18,"High")+COUNTIF($B$18,"Very High")>=$B$16)),1E+99,$J22) -> 0.86284235 | L22: =IF(OR($D22=$B$8,$D22=$B$9,$J22>=1E+99,AND(OR(LOWER($O22)="high",LOWER($O22)="very high"),COUNTIF($B$18:$B$19,"High")+COUNTIF($B$18:$B$19,"Very High")>=$B$16)),1E+99,$J22) -> 0.86284235 | M22: =IF(OR($D22=$B$8,$D22=$B$9,$D22=$B$10,$J22>=1E+99,AND(OR(LOWER($O22)="high",LOWER($O22)="very high"),COUNTIF($B$18:$B$20,"High")+COUNTIF($B$18:$B$20,"Very High")>=$B$16)),1E+99,$J22) -> 0.86284235 | N22: ='Precon Decks'!P22 -> Precon | O22: ='Precon Decks'!J22 -> Medium
C23: ='Precon Decks'!A23 -> 1 | D23: ='Precon Decks'!E23 -> Tinker Time | E23: ='Precon Decks'!H23 -> 3 | F23: ='Precon Decks'!G23 -> 6 | G23: ='Precon Decks'!I23 -> Medium | H23: ='Precon Decks'!M23+$B$6/1000000 -> 0.60148918 | I23: =IF(AND($C23=1,$D23<>"",$E23=$B$1,$F23>=$B$2,$F23<=$B$3,IF(LOWER($B$4)="yes",LOWER($G23)<>"fast",TRUE()),IF(LOWER($B$14)="any",TRUE(),LOWER($N23)=LOWER($B$14)),IF(LOWER($B$15)="any",TRUE(),IF(LOWER($B$15)="exclude very high",LOWER($O23)<>"very high",IF(LOWER($B$15)="low-medium only",OR(LOWER($O23)="low",LOWER($O23)="medium"),TRUE())))),1,0) -> 1 | J23: =IF($I23=1,$H23,1E+99) -> 0.60148918 | K23: =IF(OR($D23=$B$8,$J23>=1E+99,AND(OR(LOWER($O23)="high",LOWER($O23)="very high"),COUNTIF($B$18,"High")+COUNTIF($B$18,"Very High")>=$B$16)),1E+99,$J23) -> 0.60148918 | L23: =IF(OR($D23=$B$8,$D23=$B$9,$J23>=1E+99,AND(OR(LOWER($O23)="high",LOWER($O23)="very high"),COUNTIF($B$18:$B$19,"High")+COUNTIF($B$18:$B$19,"Very High")>=$B$16)),1E+99,$J23) -> 0.60148918 | M23: =IF(OR($D23=$B$8,$D23=$B$9,$D23=$B$10,$J23>=1E+99,AND(OR(LOWER($O23)="high",LOWER($O23)="very high"),COUNTIF($B$18:$B$20,"High")+COUNTIF($B$18:$B$20,"Very High")>=$B$16)),1E+99,$J23) -> 0.60148918 | N23: ='Precon Decks'!P23 -> Precon | O23: ='Precon Decks'!J23 -> Medium
C24: ='Precon Decks'!A24 -> 1 | D24: ='Precon Decks'!E24 -> Blast from the Past | E24: ='Precon Decks'!H24 -> 3 | F24: ='Precon Decks'!G24 -> 6 | G24: ='Precon Decks'!I24 -> Medium | H24: ='Precon Decks'!M24+$B$6/1000000 -> 0.7864744 | I24: =IF(AND($C24=1,$D24<>"",$E24=$B$1,$F24>=$B$2,$F24<=$B$3,IF(LOWER($B$4)="yes",LOWER($G24)<>"fast",TRUE()),IF(LOWER($B$14)="any",TRUE(),LOWER($N24)=LOWER($B$14)),IF(LOWER($B$15)="any",TRUE(),IF(LOWER($B$15)="exclude very high",LOWER($O24)<>"very high",IF(LOWER($B$15)="low-medium only",OR(LOWER($O24)="low",LOWER($O24)="medium"),TRUE())))),1,0) -> 1 | J24: =IF($I24=1,$H24,1E+99) -> 0.7864744 | K24: =IF(OR($D24=$B$8,$J24>=1E+99,AND(OR(LOWER($O24)="high",LOWER($O24)="very high"),COUNTIF($B$18,"High")+COUNTIF($B$18,"Very High")>=$B$16)),1E+99,$J24) -> 0.7864744 | L24: =IF(OR($D24=$B$8,$D24=$B$9,$J24>=1E+99,AND(OR(LOWER($O24)="high",LOWER($O24)="very high"),COUNTIF($B$18:$B$19,"High")+COUNTIF($B$18:$B$19,"Very High")>=$B$16)),1E+99,$J24) -> 0.7864744 | M24: =IF(OR($D24=$B$8,$D24=$B$9,$D24=$B$10,$J24>=1E+99,AND(OR(LOWER($O24)="high",LOWER($O24)="very high"),COUNTIF($B$18:$B$20,"High")+COUNTIF($B$18:$B$20,"Very High")>=$B$16)),1E+99,$J24) -> 0.7864744 | N24: ='Precon Decks'!P24 -> Precon | O24: ='Precon Decks'!J24 -> Medium
C25: ='Precon Decks'!A25 -> 1 | D25: ='Precon Decks'!E25 -> Masters of Evil | E25: ='Precon Decks'!H25 -> 3 | F25: ='Precon Decks'!G25 -> 6 | G25: ='Precon Decks'!I25 -> Medium | H25: ='Precon Decks'!M25+$B$6/1000000 -> 0.4252222 | I25: =IF(AND($C25=1,$D25<>"",$E25=$B$1,$F25>=$B$2,$F25<=$B$3,IF(LOWER($B$4)="yes",LOWER($G25)<>"fast",TRUE()),IF(LOWER($B$14)="any",TRUE(),LOWER($N25)=LOWER($B$14)),IF(LOWER($B$15)="any",TRUE(),IF(LOWER($B$15)="exclude very high",LOWER($O25)<>"very high",IF(LOWER($B$15)="low-medium only",OR(LOWER($O25)="low",LOWER($O25)="medium"),TRUE())))),1,0) -> 1 | J25: =IF($I25=1,$H25,1E+99) -> 0.4252222 | K25: =IF(OR($D25=$B$8,$J25>=1E+99,AND(OR(LOWER($O25)="high",LOWER($O25)="very high"),COUNTIF($B$18,"High")+COUNTIF($B$18,"Very High")>=$B$16)),1E+99,$J25) -> 0.4252222 | L25: =IF(OR($D25=$B$8,$D25=$B$9,$J25>=1E+99,AND(OR(LOWER($O25)="high",LOWER($O25)="very high"),COUNTIF($B$18:$B$19,"High")+COUNTIF($B$18:$B$19,"Very High")>=$B$16)),1E+99,$J25) -> 0.4252222 | M25: =IF(OR($D25=$B$8,$D25=$B$9,$D25=$B$10,$J25>=1E+99,AND(OR(LOWER($O25)="high",LOWER($O25)="very high"),COUNTIF($B$18:$B$20,"High")+COUNTIF($B$18:$B$20,"Very High")>=$B$16)),1E+99,$J25) -> 0.4252222 | N25: ='Precon Decks'!P25 -> Precon | O25: ='Precon Decks'!J25 -> Medium
C26: ='Precon Decks'!A26 -> 1 | D26: ='Precon Decks'!E26 -> Paradox Power | E26: ='Precon Decks'!H26 -> 3 | F26: ='Precon Decks'!G26 -> 6.5 | G26: ='Precon Decks'!I26 -> Medium | H26: ='Precon Decks'!M26+$B$6/1000000 -> 0.13123838 | I26: =IF(AND($C26=1,$D26<>"",$E26=$B$1,$F26>=$B$2,$F26<=$B$3,IF(LOWER($B$4)="yes",LOWER($G26)<>"fast",TRUE()),IF(LOWER($B$14)="any",TRUE(),LOWER($N26)=LOWER($B$14)),IF(LOWER($B$15)="any",TRUE(),IF(LOWER($B$15)="exclude very high",LOWER($O26)<>"very high",IF(LOWER($B$15)="low-medium only",OR(LOWER($O26)="low",LOWER($O26)="medium"),TRUE())))),1,0) -> 1 | J26: =IF($I26=1,$H26,1E+99) -> 0.13123838 | K26: =IF(OR($D26=$B$8,$J26>=1E+99,AND(OR(LOWER($O26)="high",LOWER($O26)="very high"),COUNTIF($B$18,"High")+COUNTIF($B$18,"Very High")>=$B$16)),1E+99,$J26) -> 0.13123838 | L26: =IF(OR($D26=$B$8,$D26=$B$9,$J26>=1E+99,AND(OR(LOWER($O26)="high",LOWER($O26)="very high"),COUNTIF($B$18:$B$19,"High")+COUNTIF($B$18:$B$19,"Very High")>=$B$16)),1E+99,$J26) -> 0.13123838 | M26: =IF(OR($D26=$B$8,$D26=$B$9,$D26=$B$10,$J26>=1E+99,AND(OR(LOWER($O26)="high",LOWER($O26)="very high"),COUNTIF($B$18:$B$20,"High")+COUNTIF($B$18:$B$20,"Very High")>=$B$16)),1E+99,$J26) -> 1e+99 | N26: ='Precon Decks'!P26 -> Precon | O26: ='Precon Decks'!J26 -> High
C27: ='Precon Decks'!A27 -> 1 | D27: ='Precon Decks'!E27 -> Timey-Wimey | E27: ='Precon Decks'!H27 -> 4 | F27: ='Precon Decks'!G27 -> 7 | G27: ='Precon Decks'!I27 -> Fast | H27: ='Precon Decks'!M27+$B$6/1000000 -> 0.84817316 | I27: =IF(AND($C27=1,$D27<>"",$E27=$B$1,$F27>=$B$2,$F27<=$B$3,IF(LOWER($B$4)="yes",LOWER($G27)<>"fast",TRUE()),IF(LOWER($B$14)="any",TRUE(),LOWER($N27)=LOWER($B$14)),IF(LOWER($B$15)="any",TRUE(),IF(LOWER($B$15)="exclude very high",LOWER($O27)<>"very high",IF(LOWER($B$15)="low-medium only",OR(LOWER($O27)="low",LOWER($O27)="medium"),TRUE())))),1,0) -> 0 | J27: =IF($I27=1,$H27,1E+99) -> 1e+99 | K27: =IF(OR($D27=$B$8,$J27>=1E+99,AND(OR(LOWER($O27)="high",LOWER($O27)="very high"),COUNTIF($B$18,"High")+COUNTIF($B$18,"Very High")>=$B$16)),1E+99,$J27) -> 1e+99 | L27: =IF(OR($D27=$B$8,$D27=$B$9,$J27>=1E+99,AND(OR(LOWER($O27)="high",LOWER($O27)="very high"),COUNTIF($B$18:$B$19,"High")+COUNTIF($B$18:$B$19,"Very High")>=$B$16)),1E+99,$J27) -> 1e+99 | M27: =IF(OR($D27=$B$8,$D27=$B$9,$D27=$B$10,$J27>=1E+99,AND(OR(LOWER($O27)="high",LOWER($O27)="very high"),COUNTIF($B$18:$B$20,"High")+COUNTIF($B$18:$B$20,"Very High")>=$B$16)),1E+99,$J27) -> 1e+99 | N27: ='Precon Decks'!P27 -> Precon | O27: ='Precon Decks'!J27 -> High
C28: ='Precon Decks'!A28 -> 1 | D28: ='Precon Decks'!E28 -> Ahoy Mateys | E28: ='Precon Decks'!H28 -> 2 | F28: ='Precon Decks'!G28 -> 5.5 | G28: ='Precon Decks'!I28 -> Medium | H28: ='Precon Decks'!M28+$B$6/1000000 -> 0.70868413 | I28: =IF(AND($C28=1,$D28<>"",$E28=$B$1,$F28>=$B$2,$F28<=$B$3,IF(LOWER($B$4)="yes",LOWER($G28)<>"fast",TRUE()),IF(LOWER($B$14)="any",TRUE(),LOWER($N28)=LOWER($B$14)),IF(LOWER($B$15)="any",TRUE(),IF(LOWER($B$15)="exclude very high",LOWER($O28)<>"very high",IF(LOWER($B$15)="low-medium only",OR(LOWER($O28)="low",LOWER($O28)="medium"),TRUE())))),1,0) -> 0 | J28: =IF($I28=1,$H28,1E+99) -> 1e+99 | K28: =IF(OR($D28=$B$8,$J28>=1E+99,AND(OR(LOWER($O28)="high",LOWER($O28)="very high"),COUNTIF($B$18,"High")+COUNTIF($B$18,"Very High")>=$B$16)),1E+99,$J28) -> 1e+99 | L28: =IF(OR($D28=$B$8,$D28=$B$9,$J28>=1E+99,AND(OR(LOWER($O28)="high",LOWER($O28)="very high"),COUNTIF($B$18:$B$19,"High")+COUNTIF($B$18:$B$19,"Very High")>=$B$16)),1E+99,$J28) -> 1e+99 | M28: =IF(OR($D28=$B$8,$D28=$B$9,$D28=$B$10,$J28>=1E+99,AND(OR(LOWER($O28)="high",LOWER($O28)="very high"),COUNTIF($B$18:$B$20,"High")+COUNTIF($B$18:$B$20,"Very High")>=$B$16)),1E+99,$J28) -> 1e+99 | N28: ='Precon Decks'!P28 -> Precon | O28: ='Precon Decks'!J28 -> Medium
C29: ='Precon Decks'!A29 -> 1 | D29: ='Precon Decks'!E29 -> Blood Rites | E29: ='Precon Decks'!H29 -> 3 | F29: ='Precon Decks'!G29 -> 6 | G29: ='Precon Decks'!I29 -> Medium | H29: ='Precon Decks'!M29+$B$6/1000000 -> 0.84500782 | I29: =IF(AND($C29=1,$D29<>"",$E29=$B$1,$F29>=$B$2,$F29<=$B$3,IF(LOWER($B$4)="yes",LOWER($G29)<>"fast",TRUE()),IF(LOWER($B$14)="any",TRUE(),LOWER($N29)=LOWER($B$14)),IF(LOWER($B$15)="any",TRUE(),IF(LOWER($B$15)="exclude very high",LOWER($O29)<>"very high",IF(LOWER($B$15)="low-medium only",OR(LOWER($O29)="low",LOWER($O29)="medium"),TRUE())))),1,0) -> 1 | J29: =IF($I29=1,$H29,1E+99) -> 0.84500782 | K29: =IF(OR($D29=$B$8,$J29>=1E+99,AND(OR(LOWER($O29)="high",LOWER($O29)="very high"),COUNTIF($B$18,"High")+COUNTIF($B$18,"Very High")>=$B$16)),1E+99,$J29) -> 0.84500782 | L29: =IF(OR($D29=$B$8,$D29=$B$9,$J29>=1E+99,AND(OR(LOWER($O29)="high",LOWER($O29)="very high"),COUNTIF($B$18:$B$19,"High")+COUNTIF($B$18:$B$19,"Very High")>=$B$16)),1E+99,$J29) -> 0.84500782 | M29: =IF(OR($D29=$B$8,$D29=$B$9,$D29=$B$10,$J29>=1E+99,AND(OR(LOWER($O29)="high",LOWER($O29)="very high"),COUNTIF($B$18:$B$20,"High")+COUNTIF($B$18:$B$20,"Very High")>=$B$16)),1E+99,$J29) -> 0.84500782 | N29: ='Precon Decks'!P29 -> Precon | O29: ='Precon Decks'!J29 -> Medium
C30: ='Precon Decks'!A30 -> 1 | D30: ='Precon Decks'!E30 -> Explorers of the Deep | E30: ='Precon Decks'!H30 -> 4 | F30: ='Precon Decks'!G30 -> 7 | G30: ='Precon Decks'!I30 -> Medium | H30: ='Precon Decks'!M30+$B$6/1000000 -> 0.64404722 | I30: =IF(AND($C30=1,$D30<>"",$E30=$B$1,$F30>=$B$2,$F30<=$B$3,IF(LOWER($B$4)="yes",LOWER($G30)<>"fast",TRUE()),IF(LOWER($B$14)="any",TRUE(),LOWER($N30)=LOWER($B$14)),IF(LOWER($B$15)="any",TRUE(),IF(LOWER($B$15)="exclude very high",LOWER($O30)<>"very high",IF(LOWER($B$15)="low-medium only",OR(LOWER($O30)="low",LOWER($O30)="medium"),TRUE())))),1,0) -> 0 | J30: =IF($I30=1,$H30,1E+99) -> 1e+99 | K30: =IF(OR($D30=$B$8,$J30>=1E+99,AND(OR(LOWER($O30)="high",LOWER($O30)="very high"),COUNTIF($B$18,"High")+COUNTIF($B$18,"Very High")>=$B$16)),1E+99,$J30) -> 1e+99 | L30: =IF(OR($D30=$B$8,$D30=$B$9,$J30>=1E+99,AND(OR(LOWER($O30)="high",LOWER($O30)="very high"),COUNTIF($B$18:$B$19,"High")+COUNTIF($B$18:$B$19,"Very High")>=$B$16)),1E+99,$J30) -> 1e+99 | M30: =IF(OR($D30=$B$8,$D30=$B$9,$D30=$B$10,$J30>=1E+99,AND(OR(LOWER($O30)="high",LOWER($O30)="very high"),COUNTIF($B$18:$B$20,"High")+COUNTIF($B$18:$B$20,"Very High")>=$B$16)),1E+99,$J30) -> 1e+99 | N30: ='Precon Decks'!P30 -> Precon | O30: ='Precon Decks'!J30 -> High
C31: ='Precon Decks'!A31 -> 1 | D31: ='Precon Decks'!E31 -> Veloci-Ramp-Tor | E31: ='Precon Decks'!H31 -> 3 | F31: ='Precon Decks'!G31 -> 6.8 | G31: ='Precon Decks'!I31 -> Medium | H31: ='Precon Decks'!M31+$B$6/1000000 -> 0.30829831 | I31: =IF(AND($C31=1,$D31<>"",$E31=$B$1,$F31>=$B$2,$F31<=$B$3,IF(LOWER($B$4)="yes",LOWER($G31)<>"fast",TRUE()),IF(LOWER($B$14)="any",TRUE(),LOWER($N31)=LOWER($B$14)),IF(LOWER($B$15)="any",TRUE(),IF(LOWER($B$15)="exclude very high",LOWER($O31)<>"very high",IF(LOWER($B$15)="low-medium only",OR(LOWER($O31)="low",LOWER($O31)="medium"),TRUE())))),1,0) -> 1 | J31: =IF($I31=1,$H31,1E+99) -> 0.30829831 | K31: =IF(OR($D31=$B$8,$J31>=1E+99,AND(OR(LOWER($O31)="high",LOWER($O31)="very high"),COUNTIF($B$18,"High")+COUNTIF($B$18,"Very High")>=$B$16)),1E+99,$J31) -> 0.30829831 | L31: =IF(OR($D31=$B$8,$D31=$B$9,$J31>=1E+99,AND(OR(LOWER($O31)="high",LOWER($O31)="very high"),COUNTIF($B$18:$B$19,"High")+COUNTIF($B$18:$B$19,"Very High")>=$B$16)),1E+99,$J31) -> 0.30829831 | M31: =IF(OR($D31=$B$8,$D31=$B$9,$D31=$B$10,$J31>=1E+99,AND(OR(LOWER($O31)="high",LOWER($O31)="very high"),COUNTIF($B$18:$B$20,"High")+COUNTIF($B$18:$B$20,"Very High")>=$B$16)),1E+99,$J31) -> 1e+99 | N31: ='Precon Decks'!P31 -> Precon | O31: ='Precon Decks'!J31 -> High
C32: ='Precon Decks'!A32 -> 1 | D32: ='Precon Decks'!E32 -> Raining Cats and Dogs | E32: ='Precon Decks'!H32 -> 3 | F32: ='Precon Decks'!G32 -> 6.5 | G32: ='Precon Decks'!I32 -> Medium | H32: ='Precon Decks'!M32+$B$6/1000000 -> 0.5167457 | I32: =IF(AND($C32=1,$D32<>"",$E32=$B$1,$F32>=$B$2,$F32<=$B$3,IF(LOWER($B$4)="yes",LOWER($G32)<>"fast",TRUE()),IF(LOWER($B$14)="any",TRUE(),LOWER($N32)=LOWER($B$14)),IF(LOWER($B$15)="any",TRUE(),IF(LOWER($B$15)="exclude very high",LOWER($O32)<>"very high",IF(LOWER($B$15)="low-medium only",OR(LOWER($O32)="low",LOWER($O32)="medium"),TRUE())))),1,0) -> 1 | J32: =IF($I32=1,$H32,1E+99) -> 0.5167457 | K32: =IF(OR($D32=$B$8,$J32>=1E+99,AND(OR(LOWER($O32)="high",LOWER($O32)="very high"),COUNTIF($B$18,"High")+COUNTIF($B$18,"Very High")>=$B$16)),1E+99,$J32) -> 0.5167457 | L32: =IF(OR($D32=$B$8,$D32=$B$9,$J32>=1E+99,AND(OR(LOWER($O32)="high",LOWER($O32)="very high"),COUNTIF($B$18:$B$19,"High")+COUNTIF($B$18:$B$19,"Very High")>=$B$16)),1E+99,$J32) -> 0.5167457 | M32: =IF(OR($D32=$B$8,$D32=$B$9,$D32=$B$10,$J32>=1E+99,AND(OR(LOWER($O32)="high",LOWER($O32)="very high"),COUNTIF($B$18:$B$20,"High")+COUNTIF($B$18:$B$20,"Very High")>=$B$16)),1E+99,$J32) -> 1e+99 | N32: ='Precon Decks'!P32 -> Precon | O32: ='Precon Decks'!J32 -> High
C33: ='Precon Decks'!A33 -> 1 | D33: ='Precon Decks'!E33 -> Animated Army | E33: ='Precon Decks'!H33 -> 3 | F33: ='Precon Decks'!G33 -> 6 | G33: ='Precon Decks'!I33 -> Medium | H33: ='Precon Decks'!M33+$B$6/1000000 -> 0.50993882 | I33: =IF(AND($C33=1,$D33<>"",$E33=$B$1,$F33>=$B$2,$F33<=$B$3,IF(LOWER($B$4)="yes",LOWER($G33)<>"fast",TRUE()),IF(LOWER($B$14)="any",TRUE(),LOWER($N33)=LOWER($B$14)),IF(LOWER($B$15)="any",TRUE(),IF(LOWER($B$15)="exclude very high",LOWER($O33)<>"very high",IF(LOWER($B$15)="low-medium only",OR(LOWER($O33)="low",LOWER($O33)="medium"),TRUE())))),1,0) -> 1 | J33: =IF($I33=1,$H33,1E+99) -> 0.50993882 | K33: =IF(OR($D33=$B$8,$J33>=1E+99,AND(OR(LOWER($O33)="high",LOWER($O33)="very high"),COUNTIF($B$18,"High")+COUNTIF($B$18,"Very High")>=$B$16)),1E+99,$J33) -> 0.50993882 | L33: =IF(OR($D33=$B$8,$D33=$B$9,$J33>=1E+99,AND(OR(LOWER($O33)="high",LOWER($O33)="very high"),COUNTIF($B$18:$B$19,"High")+COUNTIF($B$18:$B$19,"Very High")>=$B$16)),1E+99,$J33) -> 0.50993882 | M33: =IF(OR($D33=$B$8,$D33=$B$9,$D33=$B$10,$J33>=1E+99,AND(OR(LOWER($O33)="high",LOWER($O33)="very high"),COUNTIF($B$18:$B$20,"High")+COUNTIF($B$18:$B$20,"Very High")>=$B$16)),1E+99,$J33) -> 0.50993882 | N33: ='Precon Decks'!P33 -> Precon | O33: ='Precon Decks'!J33 -> Medium
... C1000: ='Precon Decks'!A1000 | D1000: ='Precon Decks'!E1000 | E1000: ='Precon Decks'!H1000 | F1000: ='Precon Decks'!G1000 | G1000: ='Precon Decks'!I1000 | H1000: ='Precon Decks'!M1000+$B$6/1000000 -> 1e-06 | I1000: =IF(AND($C1000=1,$D1000<>"",$E1000=$B$1,$F1000>=$B$2,$F1000<=$B$3,IF(LOWER($B$4)="yes",LOWER($G1000)<>"fast",TRUE()),IF(LOWER($B$14)="any",TRUE(),LOWER($N1000)=LOWER($B$14)),IF(LOWER($B$15)="any",TRUE(),IF(LOWER($B$15)="exclude very high",LOWER($O1000)<>"very high",IF(LOWER($B$15)="low-medium only",OR(LOWER($O1000)="low",LOWER($O1000)="medium"),TRUE())))),1,0) -> 0 | J1000: =IF($I1000=1,$H1000,1E+99) -> 1e+99 | K1000: =IF(OR($D1000=$B$8,$J1000>=1E+99,AND(OR(LOWER($O1000)="high",LOWER($O1000)="very high"),COUNTIF($B$18,"High")+COUNTIF($B$18,"Very High")>=$B$16)),1E+99,$J1000) -> 1e+99 | L1000: =IF(OR($D1000=$B$8,$D1000=$B$9,$J1000>=1E+99,AND(OR(LOWER($O1000)="high",LOWER($O1000)="very high"),COUNTIF($B$18:$B$19,"High")+COUNTIF($B$18:$B$19,"Very High")>=$B$16)),1E+99,$J1000) -> 1e+99 | M1000: =IF(OR($D1000=$B$8,$D1000=$B$9,$D1000=$B$10,$J1000>=1E+99,AND(OR(LOWER($O1000)="high",LOWER($O1000)="very high"),COUNTIF($B$18:$B$20,"High")+COUNTIF($B$18:$B$20,"Very High")>=$B$16)),1E+99,$J1000) -> 1e+99 | N1000: ='Precon Decks'!P1000 | O1000: ='Precon Decks'!J1000
C1001: ='Homebrew Decks'!A2 -> 1 | D1001: ='Homebrew Decks'!E2 -> Giada's Ascension | E1001: ='Homebrew Decks'!H2 -> 3 | F1001: ='Homebrew Decks'!G2 -> 6.8 | G1001: ='Homebrew Decks'!I2 -> Medium | H1001: ='Homebrew Decks'!M2+$B$6/1000000 -> 0.70020674 | I1001: =IF(AND($C1001=1,$D1001<>"",$E1001=$B$1,$F1001>=$B$2,$F1001<=$B$3,IF(LOWER($B$4)="yes",LOWER($G1001)<>"fast",TRUE()),IF(LOWER($B$14)="any",TRUE(),LOWER($N1001)=LOWER($B$14)),IF(LOWER($B$15)="any",TRUE(),IF(LOWER($B$15)="exclude very high",LOWER($O1001)<>"very high",IF(LOWER($B$15)="low-medium only",OR(LOWER($O1001)="low",LOWER($O1001)="medium"),TRUE())))),1,0) -> 1 | J1001: =IF($I1001=1,$H1001,1E+99) -> 0.70020674 | K1001: =IF(OR($D1001=$B$8,$J1001>=1E+99,AND(OR(LOWER($O1001)="high",LOWER($O1001)="very high"),COUNTIF($B$18,"High")+COUNTIF($B$18,"Very High")>=$B$16)),1E+99,$J1001) -> 0.70020674 | L1001: =IF(OR($D1001=$B$8,$D1001=$B$9,$J1001>=1E+99,AND(OR(LOWER($O1001)="high",LOWER($O1001)="very high"),COUNTIF($B$18:$B$19,"High")+COUNTIF($B$18:$B$19,"Very High")>=$B$16)),1E+99,$J1001) -> 0.70020674 | M1001: =IF(OR($D1001=$B$8,$D1001=$B$9,$D1001=$B$10,$J1001>=1E+99,AND(OR(LOWER($O1001)="high",LOWER($O1001)="very high"),COUNTIF($B$18:$B$20,"High")+COUNTIF($B$18:$B$20,"Very High")>=$B$16)),1E+99,$J1001) -> 0.70020674 | N1001: ='Homebrew Decks'!P2 -> Homebrew | O1001: ='Homebrew Decks'!J2 -> Medium
C1002: ='Homebrew Decks'!A3 -> 1 | D1002: ='Homebrew Decks'!E3 -> Silent and Deadly | E1002: ='Homebrew Decks'!H3 -> 4 | F1002: ='Homebrew Decks'!G3 -> 7.2 | G1002: ='Homebrew Decks'!I3 -> Medium | H1002: ='Homebrew Decks'!M3+$B$6/1000000 -> 0.97190371 | I1002: =IF(AND($C1002=1,$D1002<>"",$E1002=$B$1,$F1002>=$B$2,$F1002<=$B$3,IF(LOWER($B$4)="yes",LOWER($G1002)<>"fast",TRUE()),IF(LOWER($B$14)="any",TRUE(),LOWER($N1002)=LOWER($B$14)),IF(LOWER($B$15)="any",TRUE(),IF(LOWER($B$15)="exclude very high",LOWER($O1002)<>"very high",IF(LOWER($B$15)="low-medium only",OR(LOWER($O1002)="low",LOWER($O1002)="medium"),TRUE())))),1,0) -> 0 | J1002: =IF($I1002=1,$H1002,1E+99) -> 1e+99 | K1002: =IF(OR($D1002=$B$8,$J1002>=1E+99,AND(OR(LOWER($O1002)="high",LOWER($O1002)="very high"),COUNTIF($B$18,"High")+COUNTIF($B$18,"Very High")>=$B$16)),1E+99,$J1002) -> 1e+99 | L1002: =IF(OR($D1002=$B$8,$D1002=$B$9,$J1002>=1E+99,AND(OR(LOWER($O1002)="high",LOWER($O1002)="very high"),COUNTIF($B$18:$B$19,"High")+COUNTIF($B$18:$B$19,"Very High")>=$B$16)),1E+99,$J1002) -> 1e+99 | M1002: =IF(OR($D1002=$B$8,$D1002=$B$9,$D1002=$B$10,$J1002>=1E+99,AND(OR(LOWER($O1002)="high",LOWER($O1002)="very high"),COUNTIF($B$18:$B$20,"High")+COUNTIF($B$18:$B$20,"Very High")>=$B$16)),1E+99,$J1002) -> 1e+99 | N1002: ='Homebrew Decks'!P3 -> Homebrew | O1002: ='Homebrew Decks'!J3 -> High
C1003: ='Homebrew Decks'!A4 -> 1 | D1003: ='Homebrew Decks'!E4 -> Oloro's Tribute | E1003: ='Homebrew Decks'!H4 -> 4 | F1003: ='Homebrew Decks'!G4 -> 7.6 | G1003: ='Homebrew Decks'!I4 -> Medium | H1003: ='Homebrew Decks'!M4+$B$6/1000000 -> 0.70642785 | I1003: =IF(AND($C1003=1,$D1003<>"",$E1003=$B$1,$F1003>=$B$2,$F1003<=$B$3,IF(LOWER($B$4)="yes",LOWER($G1003)<>"fast",TRUE()),IF(LOWER($B$14)="any",TRUE(),LOWER($N1003)=LOWER($B$14)),IF(LOWER($B$15)="any",TRUE(),IF(LOWER($B$15)="exclude very high",LOWER($O1003)<>"very high",IF(LOWER($B$15)="low-medium only",OR(LOWER($O1003)="low",LOWER($O1003)="medium"),TRUE())))),1,0) -> 0 | J1003: =IF($I1003=1,$H1003,1E+99) -> 1e+99 | K1003: =IF(OR($D1003=$B$8,$J1003>=1E+99,AND(OR(LOWER($O1003)="high",LOWER($O1003)="very high"),COUNTIF($B$18,"High")+COUNTIF($B$18,"Very High")>=$B$16)),1E+99,$J1003) -> 1e+99 | L1003: =IF(OR($D1003=$B$8,$D1003=$B$9,$J1003>=1E+99,AND(OR(LOWER($O1003)="high",LOWER($O1003)="very high"),COUNTIF($B$18:$B$19,"High")+COUNTIF($B$18:$B$19,"Very High")>=$B$16)),1E+99,$J1003) -> 1e+99 | M1003: =IF(OR($D1003=$B$8,$D1003=$B$9,$D1003=$B$10,$J1003>=1E+99,AND(OR(LOWER($O1003)="high",LOWER($O1003)="very high"),COUNTIF($B$18:$B$20,"High")+COUNTIF($B$18:$B$20,"Very High")>=$B$16)),1E+99,$J1003) -> 1e+99 | N1003: ='Homebrew Decks'!P4 -> Homebrew | O1003: ='Homebrew Decks'!J4 -> Very High
C1004: ='Homebrew Decks'!A5 -> 1 | D1004: ='Homebrew Decks'!E5 -> Squirrel! | E1004: ='Homebrew Decks'!H5 -> 4 | F1004: ='Homebrew Decks'!G5 -> 7.4 | G1004: ='Homebrew Decks'!I5 -> Medium | H1004: ='Homebrew Decks'!M5+$B$6/1000000 -> 0.45099997 | I1004: =IF(AND($C1004=1,$D1004<>"",$E1004=$B$1,$F1004>=$B$2,$F1004<=$B$3,IF(LOWER($B$4)="yes",LOWER($G1004)<>"fast",TRUE()),IF(LOWER($B$14)="any",TRUE(),LOWER($N1004)=LOWER($B$14)),IF(LOWER($B$15)="any",TRUE(),IF(LOWER($B$15)="exclude very high",LOWER($O1004)<>"very high",IF(LOWER($B$15)="low-medium only",OR(LOWER($O1004)="low",LOWER($O1004)="medium"),TRUE())))),1,0) -> 0 | J1004: =IF($I1004=1,$H1004,1E+99) -> 1e+99 | K1004: =IF(OR($D1004=$B$8,$J1004>=1E+99,AND(OR(LOWER($O1004)="high",LOWER($O1004)="very high"),COUNTIF($B$18,"High")+COUNTIF($B$18,"Very High")>=$B$16)),1E+99,$J1004) -> 1e+99 | L1004: =IF(OR($D1004=$B$8,$D1004=$B$9,$J1004>=1E+99,AND(OR(LOWER($O1004)="high",LOWER($O1004)="very high"),COUNTIF($B$18:$B$19,"High")+COUNTIF($B$18:$B$19,"Very High")>=$B$16)),1E+99,$J1004) -> 1e+99 | M1004: =IF(OR($D1004=$B$8,$D1004=$B$9,$D1004=$B$10,$J1004>=1E+99,AND(OR(LOWER($O1004)="high",LOWER($O1004)="very high"),COUNTIF($B$18:$B$20,"High")+COUNTIF($B$18:$B$20,"Very High")>=$B$16)),1E+99,$J1004) -> 1e+99 | N1004: ='Homebrew Decks'!P5 -> Homebrew | O1004: ='Homebrew Decks'!J5 -> High
C1005: ='Homebrew Decks'!A6 -> 1 | D1005: ='Homebrew Decks'!E6 -> Nils' Silent Throne | E1005: ='Homebrew Decks'!H6 -> 3 | F1005: ='Homebrew Decks'!G6 -> 6.9 | G1005: ='Homebrew Decks'!I6 -> Slow | H1005: ='Homebrew Decks'!M6+$B$6/1000000 -> 0.21529522 | I1005: =IF(AND($C1005=1,$D1005<>"",$E1005=$B$1,$F1005>=$B$2,$F1005<=$B$3,IF(LOWER($B$4)="yes",LOWER($G1005)<>"fast",TRUE()),IF(LOWER($B$14)="any",TRUE(),LOWER($N1005)=LOWER($B$14)),IF(LOWER($B$15)="any",TRUE(),IF(LOWER($B$15)="exclude very high",LOWER($O1005)<>"very high",IF(LOWER($B$15)="low-medium only",OR(LOWER($O1005)="low",LOWER($O1005)="medium"),TRUE())))),1,0) -> 1 | J1005: =IF($I1005=1,$H1005,1E+99) -> 0.21529522 | K1005: =IF(OR($D1005=$B$8,$J1005>=1E+99,AND(OR(LOWER($O1005)="high",LOWER($O1005)="very high"),COUNTIF($B$18,"High")+COUNTIF($B$18,"Very High")>=$B$16)),1E+99,$J1005) -> 0.21529522 | L1005: =IF(OR($D1005=$B$8,$D1005=$B$9,$J1005>=1E+99,AND(OR(LOWER($O1005)="high",LOWER($O1005)="very high"),COUNTIF($B$18:$B$19,"High")+COUNTIF($B$18:$B$19,"Very High")>=$B$16)),1E+99,$J1005) -> 0.21529522 | M1005: =IF(OR($D1005=$B$8,$D1005=$B$9,$D1005=$B$10,$J1005>=1E+99,AND(OR(LOWER($O1005)="high",LOWER($O1005)="very high"),COUNTIF($B$18:$B$20,"High")+COUNTIF($B$18:$B$20,"Very High")>=$B$16)),1E+99,$J1005) -> 1e+99 | N1005: ='Homebrew Decks'!P6 -> Homebrew | O1005: ='Homebrew Decks'!J6 -> High
C1006: ='Homebrew Decks'!A7 -> 1 | D1006: ='Homebrew Decks'!E7 -> The GOAT | E1006: ='Homebrew Decks'!H7 -> 4 | F1006: ='Homebrew Decks'!G7 -> 7.3 | G1006: ='Homebrew Decks'!I7 -> Medium | H1006: ='Homebrew Decks'!M7+$B$6/1000000 -> 0.36336963 | I1006: =IF(AND($C1006=1,$D1006<>"",$E1006=$B$1,$F1006>=$B$2,$F1006<=$B$3,IF(LOWER($B$4)="yes",LOWER($G1006)<>"fast",TRUE()),IF(LOWER($B$14)="any",TRUE(),LOWER($N1006)=LOWER($B$14)),IF(LOWER($B$15)="any",TRUE(),IF(LOWER($B$15)="exclude very high",LOWER($O1006)<>"very high",IF(LOWER($B$15)="low-medium only",OR(LOWER($O1006)="low",LOWER($O1006)="medium"),TRUE())))),1,0) -> 0 | J1006: =IF($I1006=1,$H1006,1E+99) -> 1e+99 | K1006: =IF(OR($D1006=$B$8,$J1006>=1E+99,AND(OR(LOWER($O1006)="high",LOWER($O1006)="very high"),COUNTIF($B$18,"High")+COUNTIF($B$18,"Very High")>=$B$16)),1E+99,$J1006) -> 1e+99 | L1006: =IF(OR($D1006=$B$8,$D1006=$B$9,$J1006>=1E+99,AND(OR(LOWER($O1006)="high",LOWER($O1006)="very high"),COUNTIF($B$18:$B$19,"High")+COUNTIF($B$18:$B$19,"Very High")>=$B$16)),1E+99,$J1006) -> 1e+99 | M1006: =IF(OR($D1006=$B$8,$D1006=$B$9,$D1006=$B$10,$J1006>=1E+99,AND(OR(LOWER($O1006)="high",LOWER($O1006)="very high"),COUNTIF($B$18:$B$20,"High")+COUNTIF($B$18:$B$20,"Very High")>=$B$16)),1E+99,$J1006) -> 1e+99 | N1006: ='Homebrew Decks'!P7 -> Homebrew | O1006: ='Homebrew Decks'!J7 -> High
...

Sheet 1v1 Generator
A1: Bracket | B1: 3 | C1: Deck Name | D1: Include | E1: Bracket | F1: Power | G1: Game Speed | H1: Random Key | I1: Eligible | J1: Pick 1 Key | K1: Pick 2 Key | L1: Deck Type | M1: Threat Perception
